<?xml version="1.0" encoding="utf-8"?>
<!-- This URDF was automatically created by SolidWorks to URDF Exporter! Originally created by Stephen Brawner (brawner@gmail.com) 
     Commit Version: 1.6.0-1-g15f4949  Build Version: 1.6.7594.29634
     For more information, please see http://wiki.ros.org/sw_urdf_exporter -->
<robot name="door">
  <link name="base_link">
    <collision>
      <origin xyz="0 -0.2 0.25" rpy="0 0 0" />
      <geometry>
        <box size="0.1 0.05 0.5"/>
      </geometry>
    </collision>

    <collision>
      <origin xyz="0 0.2 0.25" rpy="0 0 0" />
      <geometry>
        <box size="0.1 0.05 0.5"/>
      </geometry>
    </collision>

    <collision>
      <origin xyz="0 0 0.525" rpy="0 0 0" />
      <geometry>
        <box size="0.1 0.45 0.05"/>
      </geometry>
    </collision>

    <inertial>
      <origin xyz="0 0 0.0" rpy="0 0 0" />
      <mass value="5" />
      <inertia ixx="1" ixy="0.0" ixz="0.0"
                       iyy="1"   iyz="0.0"
                                 izz="1" />
    </inertial>
  </link>

  <link name="door_link">
    <collision>
      <origin xyz="-0.005 0.2 0.0" rpy="0 0 0" />
      <geometry>
        <box size="0.01 0.4 0.51"/>
      </geometry>
    </collision>

    <inertial>
      <origin xyz="0 0 0.0" rpy="0 0 0" />
      <mass value="2" />
      <inertia ixx="1" ixy="0.0" ixz="0.0"
                       iyy="1"   iyz="0.0"
                                 izz="1" />
    </inertial>
  </link>

  <joint name="hinge_joint" type="revolute">
    <origin xyz="-0.05 -0.2 0.25" rpy="0 0 0" />
    <parent link="base_link" />
    <child link="door_link" />
    <axis xyz="0 0 1" />
    <limit lower="0" upper="1.5708" effort="1" velocity="1" />
  </joint>

  <link name="handle_link">
    <inertial>
      <origin xyz="0 0 0.0" rpy="0 0 0" />
      <mass value="0.2" />
      <inertia ixx="1" ixy="0.0" ixz="0.0"
                       iyy="1"   iyz="0.0"
                                 izz="1" />
    </inertial>

    <collision>
      <origin xyz="-0.06 0.075 0.0" rpy="0 0 0" />
      <geometry>
        <box size="0.02 0.15 0.01"/>
      </geometry>
    </collision>

    <collision>
      <origin xyz="-0.03 0.0 0.0" rpy="0 1.57 0" />
      <geometry>
        <cylinder radius="0.01" length="0.06"/>
      </geometry>
    </collision>
  </link>
  <joint name="handle_joint" type="revolute">
    <origin xyz="-0.01 0.35 0" rpy="3.145 0 0" />
    <parent link="door_link" />
    <child link="handle_link" />
    <axis xyz="1 0 0" />
    <limit lower="0" upper="0.7854" effort="100" velocity="1" />
  </joint>
</robot>